Workbook

Sheet ProfitLoss
A1: Fall | C1: 2025 | D1: . | Q1: asdasd | R1: =$A$1&" "&$C$1 -> Fall 2025
B2: Income | C2: =IF($A$1="Spring", "January", IF($A$1="Fall", "July", 0)) -> July | D2: =IF($A$1="Spring", "February", IF($A$1="Fall", "August", 0)) -> August | E2: =IF($A$1="Spring", "March", IF($A$1="Fall", "September", 0)) -> September | F2: =IF($A$1="Spring", "April", IF($A$1="Fall", "October", 0)) -> October | G2: =IF($A$1="Spring", "May", IF($A$1="Fall", "November", 0)) -> November | H2: =IF($A$1="Spring", "June", IF($A$1="Fall", "December", 0)) -> December | I2: =$A$1&" Total" -> Fall Total | K2: Expenses | L2: =IF($A$1="Spring", "January", IF($A$1="Fall", "July", 0)) -> July | M2: =IF($A$1="Spring", "February", IF($A$1="Fall", "August", 0)) -> August | N2: =IF($A$1="Spring", "March", IF($A$1="Fall", "September", 0)) -> September | O2: =IF($A$1="Spring", "April", IF($A$1="Fall", "October", 0)) -> October | P2: =IF($A$1="Spring", "May", IF($A$1="Fall", "November", 0)) -> November | Q2: =IF($A$1="Spring", "June", IF($A$1="Fall", "December", 0)) -> December | R2: =$A$1&" Total" -> Fall Total | T2: asdad | U2: Semester Totals:
A3: Total Montly Income | C3: =C$4+C$10+C$17+C$24+C$31 -> 0 | D3: =D$4+D$10+D$17+D$24+D$31 -> 799.77 | E3: =E$4+E$10+E$17+E$24+E$31 -> 787.13 | F3: =F$4+F$10+F$17+F$24+F$31 -> 57.82 | G3: =G$4+G$10+G$17+G$24+G$31 -> 0 | H3: =H$4+H$10+H$17+H$24+H$31 -> 0 | I3: =I$4+I$10+I$17+I$24+I$31 -> 1644.72 | K3: Monthly Profit | L3: =C3-L4 -> -329.31 | M3: =D3-M4 -> 522.71 | N3: =E3-N4 -> 100.1 | O3: =F3-O4 -> -62.97 | P3: =G3-P4 -> 0 | Q3: =H3-Q4 -> 0 | R3: =I3-R4 -> 230.53 | T3: ="Income for "&$A$1&" of "& $C$1&":" -> Income for Fall of 2025: | V3: =SUM($I$4,$I$10,$I$17,$I$24,$I$31) -> 1644.72
A4: Member dues | B4: Monthly totals: | C4: =sum(C$5:C$9) -> 0 | D4: =sum(D$5:D$9) -> 465 | E4: =sum(E$5:E$9) -> 640 | F4: =sum(F$5:F$9) -> 0 | G4: =sum(G$5:G$9) -> 0 | H4: =sum(H$5:H$9) -> 0 | I4: =SUM(C4:H4) -> 1105 | K4: Monthly totals: | L4: =sum(L$5:L$10) -> 329.31 | M4: =sum(M$5:M$10) -> 277.06 | N4: =sum(N$5:N$10) -> 687.03 | O4: =sum(O$5:O$10) -> 120.79 | P4: =sum(P$5:P$10) -> 0 | Q4: =sum(Q$5:Q$10) -> 0 | R4: =SUM(L4:Q4) -> 1414.19 | T4: ="Expenses for "&$A$1&" of "& $C$1&":" -> Expenses for Fall of 2025: | V4: =$R$4 -> 1414.19
B5: Paypal | C5: {=INDEX(IncomeCalcs!$K$2:$O$254,MATCH(DATEVALUE(MATCH(C$2,{"January","February","March","April","May","June","July","August","September","October","November","December"},0) & "/1/" &$C$1),IncomeCalcs!$J$2:$J37,0),MATCH($B5,IncomeCalcs!$K$2:$O$2,0))} -> 0 | D5: {=INDEX(IncomeCalcs!$K$2:$O$254,MATCH(DATEVALUE(MATCH(D$2,{"January","February","March","April","May","June","July","August","September","October","November","December"},0) & "/1/" &$C$1),IncomeCalcs!$J$2:$J37,0),MATCH($B5,IncomeCalcs!$K$2:$O$2,0))} -> 75 | E5: {=INDEX(IncomeCalcs!$K$2:$O$254,MATCH(DATEVALUE(MATCH(E$2,{"January","February","March","April","May","June","July","August","September","October","November","December"},0) & "/1/" &$C$1),IncomeCalcs!$J$2:$J37,0),MATCH($B5,IncomeCalcs!$K$2:$O$2,0))} -> 130 | F5: {=INDEX(IncomeCalcs!$K$2:$O$254,MATCH(DATEVALUE(MATCH(F$2,{"January","February","March","April","May","June","July","August","September","October","November","December"},0) & "/1/" &$C$1),IncomeCalcs!$J$2:$J37,0),MATCH($B5,IncomeCalcs!$K$2:$O$2,0))} -> 0 | G5: {=INDEX(IncomeCalcs!$K$2:$O$254,MATCH(DATEVALUE(MATCH(G$2,{"January","February","March","April","May","June","July","August","September","October","November","December"},0) & "/1/" &$C$1),IncomeCalcs!$J$2:$J37,0),MATCH($B5,IncomeCalcs!$K$2:$O$2,0))} -> 0 | H5: {=INDEX(IncomeCalcs!$K$2:$O$254,MATCH(DATEVALUE(MATCH(H$2,{"January","February","March","April","May","June","July","August","September","October","November","December"},0) & "/1/" &$C$1),IncomeCalcs!$J$2:$J37,0),MATCH($B5,IncomeCalcs!$K$2:$O$2,0))} -> 0 | I5: =SUM(C5:H5) -> 205 | K5: Vet Bills | L5: =SUMIFS(Expenses!$F$4:$F37,Expenses!$E$4:$E37,$K5,Expenses!$B$4:$B37,L$2,Expenses!$C$4:$C37,$C$1) -> 0 | M5: =SUMIFS(Expenses!$F$4:$F37,Expenses!$E$4:$E37,$K5,Expenses!$B$4:$B37,M$2,Expenses!$C$4:$C37,$C$1) -> 0 | N5: =SUMIFS(Expenses!$F$4:$F37,Expenses!$E$4:$E37,$K5,Expenses!$B$4:$B37,N$2,Expenses!$C$4:$C37,$C$1) -> 414 | O5: =SUMIFS(Expenses!$F$4:$F37,Expenses!$E$4:$E37,$K5,Expenses!$B$4:$B37,O$2,Expenses!$C$4:$C37,$C$1) -> 0 | P5: =SUMIFS(Expenses!$F$4:$F37,Expenses!$E$4:$E37,$K5,Expenses!$B$4:$B37,P$2,Expenses!$C$4:$C37,$C$1) -> 0 | Q5: =SUMIFS(Expenses!$F$4:$F37,Expenses!$E$4:$E37,$K5,Expenses!$B$4:$B37,Q$2,Expenses!$C$4:$C37,$C$1) -> 0 | R5: =SUM(L5:Q5) -> 414 | T5: ="Profit for "&$A$1&" of "& $C$1&":" -> Profit for Fall of 2025: | V5: =V3-V4 -> 230.53
B6: Cashapp | C6: {=INDEX(IncomeCalcs!$K$2:$O$254,MATCH(DATEVALUE(MATCH(C$2,{"January","February","March","April","May","June","July","August","September","October","November","December"},0) & "/1/" &$C$1),IncomeCalcs!$J$2:$J37,0),MATCH($B6,IncomeCalcs!$K$2:$O$2,0))} -> 0 | D6: {=INDEX(IncomeCalcs!$K$2:$O$254,MATCH(DATEVALUE(MATCH(D$2,{"January","February","March","April","May","June","July","August","September","October","November","December"},0) & "/1/" &$C$1),IncomeCalcs!$J$2:$J37,0),MATCH($B6,IncomeCalcs!$K$2:$O$2,0))} -> 105 | E6: {=INDEX(IncomeCalcs!$K$2:$O$254,MATCH(DATEVALUE(MATCH(E$2,{"January","February","March","April","May","June","July","August","September","October","November","December"},0) & "/1/" &$C$1),IncomeCalcs!$J$2:$J37,0),MATCH($B6,IncomeCalcs!$K$2:$O$2,0))} -> 195 | F6: {=INDEX(IncomeCalcs!$K$2:$O$254,MATCH(DATEVALUE(MATCH(F$2,{"January","February","March","April","May","June","July","August","September","October","November","December"},0) & "/1/" &$C$1),IncomeCalcs!$J$2:$J37,0),MATCH($B6,IncomeCalcs!$K$2:$O$2,0))} -> 0 | G6: {=INDEX(IncomeCalcs!$K$2:$O$254,MATCH(DATEVALUE(MATCH(G$2,{"January","February","March","April","May","June","July","August","September","October","November","December"},0) & "/1/" &$C$1),IncomeCalcs!$J$2:$J37,0),MATCH($B6,IncomeCalcs!$K$2:$O$2,0))} -> 0 | H6: {=INDEX(IncomeCalcs!$K$2:$O$254,MATCH(DATEVALUE(MATCH(H$2,{"January","February","March","April","May","June","July","August","September","October","November","December"},0) & "/1/" &$C$1),IncomeCalcs!$J$2:$J37,0),MATCH($B6,IncomeCalcs!$K$2:$O$2,0))} -> 0 | I6: =SUM(C6:H6) -> 300 | K6: Food | L6: =SUMIFS(Expenses!$F$4:$F37,Expenses!$E$4:$E37,$K6,Expenses!$B$4:$B37,L$2,Expenses!$C$4:$C37,$C$1) -> 74.92 | M6: =SUMIFS(Expenses!$F$4:$F37,Expenses!$E$4:$E37,$K6,Expenses!$B$4:$B37,M$2,Expenses!$C$4:$C37,$C$1) -> 42.2 | N6: =SUMIFS(Expenses!$F$4:$F37,Expenses!$E$4:$E37,$K6,Expenses!$B$4:$B37,N$2,Expenses!$C$4:$C37,$C$1) -> 43.28 | O6: =SUMIFS(Expenses!$F$4:$F37,Expenses!$E$4:$E37,$K6,Expenses!$B$4:$B37,O$2,Expenses!$C$4:$C37,$C$1) -> 89.91 | P6: =SUMIFS(Expenses!$F$4:$F37,Expenses!$E$4:$E37,$K6,Expenses!$B$4:$B37,P$2,Expenses!$C$4:$C37,$C$1) -> 0 | Q6: =SUMIFS(Expenses!$F$4:$F37,Expenses!$E$4:$E37,$K6,Expenses!$B$4:$B37,Q$2,Expenses!$C$4:$C37,$C$1) -> 0 | R6: =SUM(L6:Q6) -> 250.31
B7: Venmo | C7: {=INDEX(IncomeCalcs!$K$2:$O$254,MATCH(DATEVALUE(MATCH(C$2,{"January","February","March","April","May","June","July","August","September","October","November","December"},0) & "/1/" &$C$1),IncomeCalcs!$J$2:$J37,0),MATCH($B7,IncomeCalcs!$K$2:$O$2,0))} -> 0 | D7: {=INDEX(IncomeCalcs!$K$2:$O$254,MATCH(DATEVALUE(MATCH(D$2,{"January","February","March","April","May","June","July","August","September","October","November","December"},0) & "/1/" &$C$1),IncomeCalcs!$J$2:$J37,0),MATCH($B7,IncomeCalcs!$K$2:$O$2,0))} -> 180 | E7: {=INDEX(IncomeCalcs!$K$2:$O$254,MATCH(DATEVALUE(MATCH(E$2,{"January","February","March","April","May","June","July","August","September","October","November","December"},0) & "/1/" &$C$1),IncomeCalcs!$J$2:$J37,0),MATCH($B7,IncomeCalcs!$K$2:$O$2,0))} -> 60 | F7: {=INDEX(IncomeCalcs!$K$2:$O$254,MATCH(DATEVALUE(MATCH(F$2,{"January","February","March","April","May","June","July","August","September","October","November","December"},0) & "/1/" &$C$1),IncomeCalcs!$J$2:$J37,0),MATCH($B7,IncomeCalcs!$K$2:$O$2,0))} -> 0 | G7: {=INDEX(IncomeCalcs!$K$2:$O$254,MATCH(DATEVALUE(MATCH(G$2,{"January","February","March","April","May","June","July","August","September","October","November","December"},0) & "/1/" &$C$1),IncomeCalcs!$J$2:$J37,0),MATCH($B7,IncomeCalcs!$K$2:$O$2,0))} -> 0 | H7: {=INDEX(IncomeCalcs!$K$2:$O$254,MATCH(DATEVALUE(MATCH(H$2,{"January","February","March","April","May","June","July","August","September","October","November","December"},0) & "/1/" &$C$1),IncomeCalcs!$J$2:$J37,0),MATCH($B7,IncomeCalcs!$K$2:$O$2,0))} -> 0 | I7: =SUM(C7:H7) -> 240 | K7: Storage Unit Fee | L7: =SUMIFS(Expenses!$F$4:$F37,Expenses!$E$4:$E37,$K7,Expenses!$B$4:$B37,L$2,Expenses!$C$4:$C37,$C$1) -> 162 | M7: =SUMIFS(Expenses!$F$4:$F37,Expenses!$E$4:$E37,$K7,Expenses!$B$4:$B37,M$2,Expenses!$C$4:$C37,$C$1) -> 54 | N7: =SUMIFS(Expenses!$F$4:$F37,Expenses!$E$4:$E37,$K7,Expenses!$B$4:$B37,N$2,Expenses!$C$4:$C37,$C$1) -> 54 | O7: =SUMIFS(Expenses!$F$4:$F37,Expenses!$E$4:$E37,$K7,Expenses!$B$4:$B37,O$2,Expenses!$C$4:$C37,$C$1) -> 0 | P7: =SUMIFS(Expenses!$F$4:$F37,Expenses!$E$4:$E37,$K7,Expenses!$B$4:$B37,P$2,Expenses!$C$4:$C37,$C$1) -> 0 | Q7: =SUMIFS(Expenses!$F$4:$F37,Expenses!$E$4:$E37,$K7,Expenses!$B$4:$B37,Q$2,Expenses!$C$4:$C37,$C$1) -> 0 | R7: =SUM(L7:Q7) -> 270
B8: Cash | C8: {=INDEX(IncomeCalcs!$K$2:$O$254,MATCH(DATEVALUE(MATCH(C$2,{"January","February","March","April","May","June","July","August","September","October","November","December"},0) & "/1/" &$C$1),IncomeCalcs!$J$2:$J37,0),MATCH($B8,IncomeCalcs!$K$2:$O$2,0))} -> 0 | D8: {=INDEX(IncomeCalcs!$K$2:$O$254,MATCH(DATEVALUE(MATCH(D$2,{"January","February","March","April","May","June","July","August","September","October","November","December"},0) & "/1/" &$C$1),IncomeCalcs!$J$2:$J37,0),MATCH($B8,IncomeCalcs!$K$2:$O$2,0))} -> 105 | E8: {=INDEX(IncomeCalcs!$K$2:$O$254,MATCH(DATEVALUE(MATCH(E$2,{"January","February","March","April","May","June","July","August","September","October","November","December"},0) & "/1/" &$C$1),IncomeCalcs!$J$2:$J37,0),MATCH($B8,IncomeCalcs!$K$2:$O$2,0))} -> 255 | F8: {=INDEX(IncomeCalcs!$K$2:$O$254,MATCH(DATEVALUE(MATCH(F$2,{"January","February","March","April","May","June","July","August","September","October","November","December"},0) & "/1/" &$C$1),IncomeCalcs!$J$2:$J37,0),MATCH($B8,IncomeCalcs!$K$2:$O$2,0))} -> 0 | G8: {=INDEX(IncomeCalcs!$K$2:$O$254,MATCH(DATEVALUE(MATCH(G$2,{"January","February","March","April","May","June","July","August","September","October","November","December"},0) & "/1/" &$C$1),IncomeCalcs!$J$2:$J37,0),MATCH($B8,IncomeCalcs!$K$2:$O$2,0))} -> 0 | H8: {=INDEX(IncomeCalcs!$K$2:$O$254,MATCH(DATEVALUE(MATCH(H$2,{"January","February","March","April","May","June","July","August","September","October","November","December"},0) & "/1/" &$C$1),IncomeCalcs!$J$2:$J37,0),MATCH($B8,IncomeCalcs!$K$2:$O$2,0))} -> 0 | I8: =SUM(C8:H8) -> 360 | K8: Website Fee | L8: =SUMIFS(Expenses!$F$4:$F37,Expenses!$E$4:$E37,$K8,Expenses!$B$4:$B37,L$2,Expenses!$C$4:$C37,$C$1) -> 51.96 | M8: =SUMIFS(Expenses!$F$4:$F37,Expenses!$E$4:$E37,$K8,Expenses!$B$4:$B37,M$2,Expenses!$C$4:$C37,$C$1) -> 74.8 | N8: =SUMIFS(Expenses!$F$4:$F37,Expenses!$E$4:$E37,$K8,Expenses!$B$4:$B37,N$2,Expenses!$C$4:$C37,$C$1) -> 25.98 | O8: =SUMIFS(Expenses!$F$4:$F37,Expenses!$E$4:$E37,$K8,Expenses!$B$4:$B37,O$2,Expenses!$C$4:$C37,$C$1) -> 0 | P8: =SUMIFS(Expenses!$F$4:$F37,Expenses!$E$4:$E37,$K8,Expenses!$B$4:$B37,P$2,Expenses!$C$4:$C37,$C$1) -> 0 | Q8: =SUMIFS(Expenses!$F$4:$F37,Expenses!$E$4:$E37,$K8,Expenses!$B$4:$B37,Q$2,Expenses!$C$4:$C37,$C$1) -> 0 | R8: =SUM(L8:Q8) -> 152.74
B9: Zelle | C9: {=INDEX(IncomeCalcs!$K$2:$O$254,MATCH(DATEVALUE(MATCH(C$2,{"January","February","March","April","May","June","July","August","September","October","November","December"},0) & "/1/" &$C$1),IncomeCalcs!$J$2:$J37,0),MATCH($B9,IncomeCalcs!$K$2:$O$2,0))} -> 0 | D9: {=INDEX(IncomeCalcs!$K$2:$O$254,MATCH(DATEVALUE(MATCH(D$2,{"January","February","March","April","May","June","July","August","September","October","November","December"},0) & "/1/" &$C$1),IncomeCalcs!$J$2:$J37,0),MATCH($B9,IncomeCalcs!$K$2:$O$2,0))} -> 0 | E9: {=INDEX(IncomeCalcs!$K$2:$O$254,MATCH(DATEVALUE(MATCH(E$2,{"January","February","March","April","May","June","July","August","September","October","November","December"},0) & "/1/" &$C$1),IncomeCalcs!$J$2:$J37,0),MATCH($B9,IncomeCalcs!$K$2:$O$2,0))} -> 0 | F9: {=INDEX(IncomeCalcs!$K$2:$O$254,MATCH(DATEVALUE(MATCH(F$2,{"January","February","March","April","May","June","July","August","September","October","November","December"},0) & "/1/" &$C$1),IncomeCalcs!$J$2:$J37,0),MATCH($B9,IncomeCalcs!$K$2:$O$2,0))} -> 0 | G9: {=INDEX(IncomeCalcs!$K$2:$O$254,MATCH(DATEVALUE(MATCH(G$2,{"January","February","March","April","May","June","July","August","September","October","November","December"},0) & "/1/" &$C$1),IncomeCalcs!$J$2:$J37,0),MATCH($B9,IncomeCalcs!$K$2:$O$2,0))} -> 0 | H9: {=INDEX(IncomeCalcs!$K$2:$O$254,MATCH(DATEVALUE(MATCH(H$2,{"January","February","March","April","May","June","July","August","September","October","November","December"},0) & "/1/" &$C$1),IncomeCalcs!$J$2:$J37,0),MATCH($B9,IncomeCalcs!$K$2:$O$2,0))} -> 0 | I9: =SUM(C9:H9) -> 0 | K9: Supplies | L9: =SUMIFS(Expenses!$F$4:$F37,Expenses!$E$4:$E37,$K9,Expenses!$B$4:$B37,L$2,Expenses!$C$4:$C37,$C$1) -> 0 | M9: =SUMIFS(Expenses!$F$4:$F37,Expenses!$E$4:$E37,$K9,Expenses!$B$4:$B37,M$2,Expenses!$C$4:$C37,$C$1) -> 58.44 | N9: =SUMIFS(Expenses!$F$4:$F37,Expenses!$E$4:$E37,$K9,Expenses!$B$4:$B37,N$2,Expenses!$C$4:$C37,$C$1) -> 142.25 | O9: =SUMIFS(Expenses!$F$4:$F37,Expenses!$E$4:$E37,$K9,Expenses!$B$4:$B37,O$2,Expenses!$C$4:$C37,$C$1) -> 0 | P9: =SUMIFS(Expenses!$F$4:$F37,Expenses!$E$4:$E37,$K9,Expenses!$B$4:$B37,P$2,Expenses!$C$4:$C37,$C$1) -> 0 | Q9: =SUMIFS(Expenses!$F$4:$F37,Expenses!$E$4:$E37,$K9,Expenses!$B$4:$B37,Q$2,Expenses!$C$4:$C37,$C$1) -> 0 | R9: =SUM(L9:Q9) -> 200.69
A10: Food/goods Fundraisers | B10: Monthly totals: | C10: =sum(C$11:C$16) -> 0 | D10: =sum(D$11:D$16) -> 258 | E10: =sum(E$11:E$16) -> 106 | F10: =sum(F$11:F$16) -> 0 | G10: =sum(G$11:G$16) -> 0 | H10: =sum(H$11:H$16) -> 0 | I10: =SUM(C10:H10) -> 364 | K10: Misc/Reimbursement | L10: =SUMIFS(Expenses!$F$4:$F37,Expenses!$E$4:$E37,$K10,Expenses!$B$4:$B37,L$2,Expenses!$C$4:$C37,$C$1) -> 40.43 | M10: =SUMIFS(Expenses!$F$4:$F37,Expenses!$E$4:$E37,$K10,Expenses!$B$4:$B37,M$2,Expenses!$C$4:$C37,$C$1) -> 47.62 | N10: =SUMIFS(Expenses!$F$4:$F37,Expenses!$E$4:$E37,$K10,Expenses!$B$4:$B37,N$2,Expenses!$C$4:$C37,$C$1) -> 7.52 | O10: =SUMIFS(Expenses!$F$4:$F37,Expenses!$E$4:$E37,$K10,Expenses!$B$4:$B37,O$2,Expenses!$C$4:$C37,$C$1) -> 30.88 | P10: =SUMIFS(Expenses!$F$4:$F37,Expenses!$E$4:$E37,$K10,Expenses!$B$4:$B37,P$2,Expenses!$C$4:$C37,$C$1) -> 0 | Q10: =SUMIFS(Expenses!$F$4:$F37,Expenses!$E$4:$E37,$K10,Expenses!$B$4:$B37,Q$2,Expenses!$C$4:$C37,$C$1) -> 0 | R10: =SUM(L10:Q10) -> 126.45
B11: Paypal | C11: {=INDEX(IncomeCalcs!$X$2:$AC$254,MATCH(DATEVALUE(MATCH(C$2,{"January","February","March","April","May","June","July","August","September","October","November","December"},0) & "/1/" &$C$1),IncomeCalcs!$W$2:$W37,0),MATCH($B11,IncomeCalcs!$X$2:$AC$2,0))} -> 0 | D11: {=INDEX(IncomeCalcs!$X$2:$AC$254,MATCH(DATEVALUE(MATCH(D$2,{"January","February","March","April","May","June","July","August","September","October","November","December"},0) & "/1/" &$C$1),IncomeCalcs!$W$2:$W37,0),MATCH($B11,IncomeCalcs!$X$2:$AC$2,0))} -> 10 | E11: {=INDEX(IncomeCalcs!$X$2:$AC$254,MATCH(DATEVALUE(MATCH(E$2,{"January","February","March","April","May","June","July","August","September","October","November","December"},0) & "/1/" &$C$1),IncomeCalcs!$W$2:$W37,0),MATCH($B11,IncomeCalcs!$X$2:$AC$2,0))} -> 0 | F11: {=INDEX(IncomeCalcs!$X$2:$AC$254,MATCH(DATEVALUE(MATCH(F$2,{"January","February","March","April","May","June","July","August","September","October","November","December"},0) & "/1/" &$C$1),IncomeCalcs!$W$2:$W37,0),MATCH($B11,IncomeCalcs!$X$2:$AC$2,0))} -> 0 | G11: {=INDEX(IncomeCalcs!$X$2:$AC$254,MATCH(DATEVALUE(MATCH(G$2,{"January","February","March","April","May","June","July","August","September","October","November","December"},0) & "/1/" &$C$1),IncomeCalcs!$W$2:$W37,0),MATCH($B11,IncomeCalcs!$X$2:$AC$2,0))} -> 0 | H11: {=INDEX(IncomeCalcs!$X$2:$AC$254,MATCH(DATEVALUE(MATCH(H$2,{"January","February","March","April","May","June","July","August","September","October","November","December"},0) & "/1/" &$C$1),IncomeCalcs!$W$2:$W37,0),MATCH($B11,IncomeCalcs!$X$2:$AC$2,0))} -> 0 | I11: =SUM(C11:H11) -> 10
B12: Cashapp | C12: {=INDEX(IncomeCalcs!$X$2:$AC$254,MATCH(DATEVALUE(MATCH(C$2,{"January","February","March","April","May","June","July","August","September","October","November","December"},0) & "/1/" &$C$1),IncomeCalcs!$W$2:$W37,0),MATCH($B12,IncomeCalcs!$X$2:$AC$2,0))} -> 0 | D12: {=INDEX(IncomeCalcs!$X$2:$AC$254,MATCH(DATEVALUE(MATCH(D$2,{"January","February","March","April","May","June","July","August","September","October","November","December"},0) & "/1/" &$C$1),IncomeCalcs!$W$2:$W37,0),MATCH($B12,IncomeCalcs!$X$2:$AC$2,0))} -> 53 | E12: {=INDEX(IncomeCalcs!$X$2:$AC$254,MATCH(DATEVALUE(MATCH(E$2,{"January","February","March","April","May","June","July","August","September","October","November","December"},0) & "/1/" &$C$1),IncomeCalcs!$W$2:$W37,0),MATCH($B12,IncomeCalcs!$X$2:$AC$2,0))} -> 75 | F12: {=INDEX(IncomeCalcs!$X$2:$AC$254,MATCH(DATEVALUE(MATCH(F$2,{"January","February","March","April","May","June","July","August","September","October","November","December"},0) & "/1/" &$C$1),IncomeCalcs!$W$2:$W37,0),MATCH($B12,IncomeCalcs!$X$2:$AC$2,0))} -> 0 | G12: {=INDEX(IncomeCalcs!$X$2:$AC$254,MATCH(DATEVALUE(MATCH(G$2,{"January","February","March","April","May","June","July","August","September","October","November","December"},0) & "/1/" &$C$1),IncomeCalcs!$W$2:$W37,0),MATCH($B12,IncomeCalcs!$X$2:$AC$2,0))} -> 0 | H12: {=INDEX(IncomeCalcs!$X$2:$AC$254,MATCH(DATEVALUE(MATCH(H$2,{"January","February","March","April","May","June","July","August","September","October","November","December"},0) & "/1/" &$C$1),IncomeCalcs!$W$2:$W37,0),MATCH($B12,IncomeCalcs!$X$2:$AC$2,0))} -> 0 | I12: =SUM(C12:H12) -> 128
B13: Venmo | C13: {=INDEX(IncomeCalcs!$X$2:$AC$254,MATCH(DATEVALUE(MATCH(C$2,{"January","February","March","April","May","June","July","August","September","October","November","December"},0) & "/1/" &$C$1),IncomeCalcs!$W$2:$W37,0),MATCH($B13,IncomeCalcs!$X$2:$AC$2,0))} -> 0 | D13: {=INDEX(IncomeCalcs!$X$2:$AC$254,MATCH(DATEVALUE(MATCH(D$2,{"January","February","March","April","May","June","July","August","September","October","November","December"},0) & "/1/" &$C$1),IncomeCalcs!$W$2:$W37,0),MATCH($B13,IncomeCalcs!$X$2:$AC$2,0))} -> 195 | E13: {=INDEX(IncomeCalcs!$X$2:$AC$254,MATCH(DATEVALUE(MATCH(E$2,{"January","February","March","April","May","June","July","August","September","October","November","December"},0) & "/1/" &$C$1),IncomeCalcs!$W$2:$W37,0),MATCH($B13,IncomeCalcs!$X$2:$AC$2,0))} -> 31 | F13: {=INDEX(IncomeCalcs!$X$2:$AC$254,MATCH(DATEVALUE(MATCH(F$2,{"January","February","March","April","May","June","July","August","September","October","November","December"},0) & "/1/" &$C$1),IncomeCalcs!$W$2:$W37,0),MATCH($B13,IncomeCalcs!$X$2:$AC$2,0))} -> 0 | G13: {=INDEX(IncomeCalcs!$X$2:$AC$254,MATCH(DATEVALUE(MATCH(G$2,{"January","February","March","April","May","June","July","August","September","October","November","December"},0) & "/1/" &$C$1),IncomeCalcs!$W$2:$W37,0),MATCH($B13,IncomeCalcs!$X$2:$AC$2,0))} -> 0 | H13: {=INDEX(IncomeCalcs!$X$2:$AC$254,MATCH(DATEVALUE(MATCH(H$2,{"January","February","March","April","May","June","July","August","September","October","November","December"},0) & "/1/" &$C$1),IncomeCalcs!$W$2:$W37,0),MATCH($B13,IncomeCalcs!$X$2:$AC$2,0))} -> 0 | I13: =SUM(C13:H13) -> 226
B14: Cash | C14: {=INDEX(IncomeCalcs!$X$2:$AC$254,MATCH(DATEVALUE(MATCH(C$2,{"January","February","March","April","May","June","July","August","September","October","November","December"},0) & "/1/" &$C$1),IncomeCalcs!$W$2:$W37,0),MATCH($B14,IncomeCalcs!$X$2:$AC$2,0))} -> 0 | D14: {=INDEX(IncomeCalcs!$X$2:$AC$254,MATCH(DATEVALUE(MATCH(D$2,{"January","February","March","April","May","June","July","August","September","October","November","December"},0) & "/1/" &$C$1),IncomeCalcs!$W$2:$W37,0),MATCH($B14,IncomeCalcs!$X$2:$AC$2,0))} -> 0 | E14: {=INDEX(IncomeCalcs!$X$2:$AC$254,MATCH(DATEVALUE(MATCH(E$2,{"January","February","March","April","May","June","July","August","September","October","November","December"},0) & "/1/" &$C$1),IncomeCalcs!$W$2:$W37,0),MATCH($B14,IncomeCalcs!$X$2:$AC$2,0))} -> 0 | F14: {=INDEX(IncomeCalcs!$X$2:$AC$254,MATCH(DATEVALUE(MATCH(F$2,{"January","February","March","April","May","June","July","August","September","October","November","December"},0) & "/1/" &$C$1),IncomeCalcs!$W$2:$W37,0),MATCH($B14,IncomeCalcs!$X$2:$AC$2,0))} -> 0 | G14: {=INDEX(IncomeCalcs!$X$2:$AC$254,MATCH(DATEVALUE(MATCH(G$2,{"January","February","March","April","May","June","July","August","September","October","November","December"},0) & "/1/" &$C$1),IncomeCalcs!$W$2:$W37,0),MATCH($B14,IncomeCalcs!$X$2:$AC$2,0))} -> 0 | H14: {=INDEX(IncomeCalcs!$X$2:$AC$254,MATCH(DATEVALUE(MATCH(H$2,{"January","February","March","April","May","June","July","August","September","October","November","December"},0) & "/1/" &$C$1),IncomeCalcs!$W$2:$W37,0),MATCH($B14,IncomeCalcs!$X$2:$AC$2,0))} -> 0 | I14: =SUM(C14:H14) -> 0
B15: Zelle | C15: {=INDEX(IncomeCalcs!$X$2:$AC$254,MATCH(DATEVALUE(MATCH(C$2,{"January","February","March","April","May","June","July","August","September","October","November","December"},0) & "/1/" &$C$1),IncomeCalcs!$W$2:$W37,0),MATCH($B15,IncomeCalcs!$X$2:$AC$2,0))} -> 0 | D15: {=INDEX(IncomeCalcs!$X$2:$AC$254,MATCH(DATEVALUE(MATCH(D$2,{"January","February","March","April","May","June","July","August","September","October","November","December"},0) & "/1/" &$C$1),IncomeCalcs!$W$2:$W37,0),MATCH($B15,IncomeCalcs!$X$2:$AC$2,0))} -> 0 | E15: {=INDEX(IncomeCalcs!$X$2:$AC$254,MATCH(DATEVALUE(MATCH(E$2,{"January","February","March","April","May","June","July","August","September","October","November","December"},0) & "/1/" &$C$1),IncomeCalcs!$W$2:$W37,0),MATCH($B15,IncomeCalcs!$X$2:$AC$2,0))} -> 0 | F15: {=INDEX(IncomeCalcs!$X$2:$AC$254,MATCH(DATEVALUE(MATCH(F$2,{"January","February","March","April","May","June","July","August","September","October","November","December"},0) & "/1/" &$C$1),IncomeCalcs!$W$2:$W37,0),MATCH($B15,IncomeCalcs!$X$2:$AC$2,0))} -> 0 | G15: {=INDEX(IncomeCalcs!$X$2:$AC$254,MATCH(DATEVALUE(MATCH(G$2,{"January","February","March","April","May","June","July","August","September","October","November","December"},0) & "/1/" &$C$1),IncomeCalcs!$W$2:$W37,0),MATCH($B15,IncomeCalcs!$X$2:$AC$2,0))} -> 0 | H15: {=INDEX(IncomeCalcs!$X$2:$AC$254,MATCH(DATEVALUE(MATCH(H$2,{"January","February","March","April","May","June","July","August","September","October","November","December"},0) & "/1/" &$C$1),IncomeCalcs!$W$2:$W37,0),MATCH($B15,IncomeCalcs!$X$2:$AC$2,0))} -> 0 | I15: =SUM(C15:H15) -> 0
B16: GoFundMe | C16: {=INDEX(IncomeCalcs!$X$2:$AC$254,MATCH(DATEVALUE(MATCH(C$2,{"January","February","March","April","May","June","July","August","September","October","November","December"},0) & "/1/" &$C$1),IncomeCalcs!$W$2:$W37,0),MATCH($B16,IncomeCalcs!$X$2:$AC$2,0))} -> 0 | D16: {=INDEX(IncomeCalcs!$X$2:$AC$254,MATCH(DATEVALUE(MATCH(D$2,{"January","February","March","April","May","June","July","August","September","October","November","December"},0) & "/1/" &$C$1),IncomeCalcs!$W$2:$W37,0),MATCH($B16,IncomeCalcs!$X$2:$AC$2,0))} -> 0 | E16: {=INDEX(IncomeCalcs!$X$2:$AC$254,MATCH(DATEVALUE(MATCH(E$2,{"January","February","March","April","May","June","July","August","September","October","November","December"},0) & "/1/" &$C$1),IncomeCalcs!$W$2:$W37,0),MATCH($B16,IncomeCalcs!$X$2:$AC$2,0))} -> 0 | F16: {=INDEX(IncomeCalcs!$X$2:$AC$254,MATCH(DATEVALUE(MATCH(F$2,{"January","February","March","April","May","June","July","August","September","October","November","December"},0) & "/1/" &$C$1),IncomeCalcs!$W$2:$W37,0),MATCH($B16,IncomeCalcs!$X$2:$AC$2,0))} -> 0 | G16: {=INDEX(IncomeCalcs!$X$2:$AC$254,MATCH(DATEVALUE(MATCH(G$2,{"January","February","March","April","May","June","July","August","September","October","November","December"},0) & "/1/" &$C$1),IncomeCalcs!$W$2:$W37,0),MATCH($B16,IncomeCalcs!$X$2:$AC$2,0))} -> 0 | H16: {=INDEX(IncomeCalcs!$X$2:$AC$254,MATCH(DATEVALUE(MATCH(H$2,{"January","February","March","April","May","June","July","August","September","October","November","December"},0) & "/1/" &$C$1),IncomeCalcs!$W$2:$W37,0),MATCH($B16,IncomeCalcs!$X$2:$AC$2,0))} -> 0 | I16: =SUM(C16:H16) -> 0
A17: Other Fundraisers | B17: Monthly totals: | C17: =sum(C$18:C$23) -> 0 | D17: =sum(D$18:D$23) -> 0 | E17: =sum(E$18:E$23) -> 0 | F17: =sum(F$18:F$23) -> 3 | G17: =sum(G$18:G$23) -> 0 | H17: =sum(H$18:H$23) -> 0 | I17: =SUM(C17:H17) -> 3
B18: Paypal | C18: {=INDEX(IncomeCalcs!$AF$2:$AK$254,MATCH(DATEVALUE(MATCH(C$2,{"January","February","March","April","May","June","July","August","September","October","November","December"},0) & "/1/" &$C$1),IncomeCalcs!$AE$2:$AE37,0),MATCH($B18,IncomeCalcs!$AF$2:$AK$2,0))} -> 0 | D18: {=INDEX(IncomeCalcs!$AF$2:$AK$254,MATCH(DATEVALUE(MATCH(D$2,{"January","February","March","April","May","June","July","August","September","October","November","December"},0) & "/1/" &$C$1),IncomeCalcs!$AE$2:$AE37,0),MATCH($B18,IncomeCalcs!$AF$2:$AK$2,0))} -> 0 | E18: {=INDEX(IncomeCalcs!$AF$2:$AK$254,MATCH(DATEVALUE(MATCH(E$2,{"January","February","March","April","May","June","July","August","September","October","November","December"},0) & "/1/" &$C$1),IncomeCalcs!$AE$2:$AE37,0),MATCH($B18,IncomeCalcs!$AF$2:$AK$2,0))} -> 0 | F18: {=INDEX(IncomeCalcs!$AF$2:$AK$254,MATCH(DATEVALUE(MATCH(F$2,{"January","February","March","April","May","June","July","August","September","October","November","December"},0) & "/1/" &$C$1),IncomeCalcs!$AE$2:$AE37,0),MATCH($B18,IncomeCalcs!$AF$2:$AK$2,0))} -> 0 | G18: {=INDEX(IncomeCalcs!$AF$2:$AK$254,MATCH(DATEVALUE(MATCH(G$2,{"January","February","March","April","May","June","July","August","September","October","November","December"},0) & "/1/" &$C$1),IncomeCalcs!$AE$2:$AE37,0),MATCH($B18,IncomeCalcs!$AF$2:$AK$2,0))} -> 0 | H18: {=INDEX(IncomeCalcs!$AF$2:$AK$254,MATCH(DATEVALUE(MATCH(H$2,{"January","February","March","April","May","June","July","August","September","October","November","December"},0) & "/1/" &$C$1),IncomeCalcs!$AE$2:$AE37,0),MATCH($B18,IncomeCalcs!$AF$2:$AK$2,0))} -> 0 | I18: =SUM(C18:H18) -> 0
B19: Cashapp | C19: {=INDEX(IncomeCalcs!$AF$2:$AK$254,MATCH(DATEVALUE(MATCH(C$2,{"January","February","March","April","May","June","July","August","September","October","November","December"},0) & "/1/" &$C$1),IncomeCalcs!$AE$2:$AE37,0),MATCH($B19,IncomeCalcs!$AF$2:$AK$2,0))} -> 0 | D19: {=INDEX(IncomeCalcs!$AF$2:$AK$254,MATCH(DATEVALUE(MATCH(D$2,{"January","February","March","April","May","June","July","August","September","October","November","December"},0) & "/1/" &$C$1),IncomeCalcs!$AE$2:$AE37,0),MATCH($B19,IncomeCalcs!$AF$2:$AK$2,0))} -> 0 | E19: {=INDEX(IncomeCalcs!$AF$2:$AK$254,MATCH(DATEVALUE(MATCH(E$2,{"January","February","March","April","May","June","July","August","September","October","November","December"},0) & "/1/" &$C$1),IncomeCalcs!$AE$2:$AE37,0),MATCH($B19,IncomeCalcs!$AF$2:$AK$2,0))} -> 0 | F19: {=INDEX(IncomeCalcs!$AF$2:$AK$254,MATCH(DATEVALUE(MATCH(F$2,{"January","February","March","April","May","June","July","August","September","October","November","December"},0) & "/1/" &$C$1),IncomeCalcs!$AE$2:$AE37,0),MATCH($B19,IncomeCalcs!$AF$2:$AK$2,0))} -> 0 | G19: {=INDEX(IncomeCalcs!$AF$2:$AK$254,MATCH(DATEVALUE(MATCH(G$2,{"January","February","March","April","May","June","July","August","September","October","November","December"},0) & "/1/" &$C$1),IncomeCalcs!$AE$2:$AE37,0),MATCH($B19,IncomeCalcs!$AF$2:$AK$2,0))} -> 0 | H19: {=INDEX(IncomeCalcs!$AF$2:$AK$254,MATCH(DATEVALUE(MATCH(H$2,{"January","February","March","April","May","June","July","August","September","October","November","December"},0) & "/1/" &$C$1),IncomeCalcs!$AE$2:$AE37,0),MATCH($B19,IncomeCalcs!$AF$2:$AK$2,0))} -> 0 | I19: =SUM(C19:H19) -> 0
B20: Venmo | C20: {=INDEX(IncomeCalcs!$AF$2:$AK$254,MATCH(DATEVALUE(MATCH(C$2,{"January","February","March","April","May","June","July","August","September","October","November","December"},0) & "/1/" &$C$1),IncomeCalcs!$AE$2:$AE37,0),MATCH($B20,IncomeCalcs!$AF$2:$AK$2,0))} -> 0 | D20: {=INDEX(IncomeCalcs!$AF$2:$AK$254,MATCH(DATEVALUE(MATCH(D$2,{"January","February","March","April","May","June","July","August","September","October","November","December"},0) & "/1/" &$C$1),IncomeCalcs!$AE$2:$AE37,0),MATCH($B20,IncomeCalcs!$AF$2:$AK$2,0))} -> 0 | E20: {=INDEX(IncomeCalcs!$AF$2:$AK$254,MATCH(DATEVALUE(MATCH(E$2,{"January","February","March","April","May","June","July","August","September","October","November","December"},0) & "/1/" &$C$1),IncomeCalcs!$AE$2:$AE37,0),MATCH($B20,IncomeCalcs!$AF$2:$AK$2,0))} -> 0 | F20: {=INDEX(IncomeCalcs!$AF$2:$AK$254,MATCH(DATEVALUE(MATCH(F$2,{"January","February","March","April","May","June","July","August","September","October","November","December"},0) & "/1/" &$C$1),IncomeCalcs!$AE$2:$AE37,0),MATCH($B20,IncomeCalcs!$AF$2:$AK$2,0))} -> 3 | G20: {=INDEX(IncomeCalcs!$AF$2:$AK$254,MATCH(DATEVALUE(MATCH(G$2,{"January","February","March","April","May","June","July","August","September","October","November","December"},0) & "/1/" &$C$1),IncomeCalcs!$AE$2:$AE37,0),MATCH($B20,IncomeCalcs!$AF$2:$AK$2,0))} -> 0 | H20: {=INDEX(IncomeCalcs!$AF$2:$AK$254,MATCH(DATEVALUE(MATCH(H$2,{"January","February","March","April","May","June","July","August","September","October","November","December"},0) & "/1/" &$C$1),IncomeCalcs!$AE$2:$AE37,0),MATCH($B20,IncomeCalcs!$AF$2:$AK$2,0))} -> 0 | I20: =SUM(C20:H20) -> 3
B21: Cash | C21: {=INDEX(IncomeCalcs!$AF$2:$AK$254,MATCH(DATEVALUE(MATCH(C$2,{"January","February","March","April","May","June","July","August","September","October","November","December"},0) & "/1/" &$C$1),IncomeCalcs!$AE$2:$AE37,0),MATCH($B21,IncomeCalcs!$AF$2:$AK$2,0))} -> 0 | D21: {=INDEX(IncomeCalcs!$AF$2:$AK$254,MATCH(DATEVALUE(MATCH(D$2,{"January","February","March","April","May","June","July","August","September","October","November","December"},0) & "/1/" &$C$1),IncomeCalcs!$AE$2:$AE37,0),MATCH($B21,IncomeCalcs!$AF$2:$AK$2,0))} -> 0 | E21: {=INDEX(IncomeCalcs!$AF$2:$AK$254,MATCH(DATEVALUE(MATCH(E$2,{"January","February","March","April","May","June","July","August","September","October","November","December"},0) & "/1/" &$C$1),IncomeCalcs!$AE$2:$AE37,0),MATCH($B21,IncomeCalcs!$AF$2:$AK$2,0))} -> 0 | F21: {=INDEX(IncomeCalcs!$AF$2:$AK$254,MATCH(DATEVALUE(MATCH(F$2,{"January","February","March","April","May","June","July","August","September","October","November","December"},0) & "/1/" &$C$1),IncomeCalcs!$AE$2:$AE37,0),MATCH($B21,IncomeCalcs!$AF$2:$AK$2,0))} -> 0 | G21: {=INDEX(IncomeCalcs!$AF$2:$AK$254,MATCH(DATEVALUE(MATCH(G$2,{"January","February","March","April","May","June","July","August","September","October","November","December"},0) & "/1/" &$C$1),IncomeCalcs!$AE$2:$AE37,0),MATCH($B21,IncomeCalcs!$AF$2:$AK$2,0))} -> 0 | H21: {=INDEX(IncomeCalcs!$AF$2:$AK$254,MATCH(DATEVALUE(MATCH(H$2,{"January","February","March","April","May","June","July","August","September","October","November","December"},0) & "/1/" &$C$1),IncomeCalcs!$AE$2:$AE37,0),MATCH($B21,IncomeCalcs!$AF$2:$AK$2,0))} -> 0 | I21: =SUM(C21:H21) -> 0
B22: Zelle | C22: {=INDEX(IncomeCalcs!$AF$2:$AK$254,MATCH(DATEVALUE(MATCH(C$2,{"January","February","March","April","May","June","July","August","September","October","November","December"},0) & "/1/" &$C$1),IncomeCalcs!$AE$2:$AE37,0),MATCH($B22,IncomeCalcs!$AF$2:$AK$2,0))} -> 0 | D22: {=INDEX(IncomeCalcs!$AF$2:$AK$254,MATCH(DATEVALUE(MATCH(D$2,{"January","February","March","April","May","June","July","August","September","October","November","December"},0) & "/1/" &$C$1),IncomeCalcs!$AE$2:$AE37,0),MATCH($B22,IncomeCalcs!$AF$2:$AK$2,0))} -> 0 | E22: {=INDEX(IncomeCalcs!$AF$2:$AK$254,MATCH(DATEVALUE(MATCH(E$2,{"January","February","March","April","May","June","July","August","September","October","November","December"},0) & "/1/" &$C$1),IncomeCalcs!$AE$2:$AE37,0),MATCH($B22,IncomeCalcs!$AF$2:$AK$2,0))} -> 0 | F22: {=INDEX(IncomeCalcs!$AF$2:$AK$254,MATCH(DATEVALUE(MATCH(F$2,{"January","February","March","April","May","June","July","August","September","October","November","December"},0) & "/1/" &$C$1),IncomeCalcs!$AE$2:$AE37,0),MATCH($B22,IncomeCalcs!$AF$2:$AK$2,0))} -> 0 | G22: {=INDEX(IncomeCalcs!$AF$2:$AK$254,MATCH(DATEVALUE(MATCH(G$2,{"January","February","March","April","May","June","July","August","September","October","November","December"},0) & "/1/" &$C$1),IncomeCalcs!$AE$2:$AE37,0),MATCH($B22,IncomeCalcs!$AF$2:$AK$2,0))} -> 0 | H22: {=INDEX(IncomeCalcs!$AF$2:$AK$254,MATCH(DATEVALUE(MATCH(H$2,{"January","February","March","April","May","June","July","August","September","October","November","December"},0) & "/1/" &$C$1),IncomeCalcs!$AE$2:$AE37,0),MATCH($B22,IncomeCalcs!$AF$2:$AK$2,0))} -> 0 | I22: =SUM(C22:H22) -> 0
B23: GoFundMe | C23: {=INDEX(IncomeCalcs!$AF$2:$AK$254,MATCH(DATEVALUE(MATCH(C$2,{"January","February","March","April","May","June","July","August","September","October","November","December"},0) & "/1/" &$C$1),IncomeCalcs!$AE$2:$AE37,0),MATCH($B23,IncomeCalcs!$AF$2:$AK$2,0))} -> 0 | D23: {=INDEX(IncomeCalcs!$AF$2:$AK$254,MATCH(DATEVALUE(MATCH(D$2,{"January","February","March","April","May","June","July","August","September","October","November","December"},0) & "/1/" &$C$1),IncomeCalcs!$AE$2:$AE37,0),MATCH($B23,IncomeCalcs!$AF$2:$AK$2,0))} -> 0 | E23: {=INDEX(IncomeCalcs!$AF$2:$AK$254,MATCH(DATEVALUE(MATCH(E$2,{"January","February","March","April","May","June","July","August","September","October","November","December"},0) & "/1/" &$C$1),IncomeCalcs!$AE$2:$AE37,0),MATCH($B23,IncomeCalcs!$AF$2:$AK$2,0))} -> 0 | F23: {=INDEX(IncomeCalcs!$AF$2:$AK$254,MATCH(DATEVALUE(MATCH(F$2,{"January","February","March","April","May","June","July","August","September","October","November","December"},0) & "/1/" &$C$1),IncomeCalcs!$AE$2:$AE37,0),MATCH($B23,IncomeCalcs!$AF$2:$AK$2,0))} -> 0 | G23: {=INDEX(IncomeCalcs!$AF$2:$AK$254,MATCH(DATEVALUE(MATCH(G$2,{"January","February","March","April","May","June","July","August","September","October","November","December"},0) & "/1/" &$C$1),IncomeCalcs!$AE$2:$AE37,0),MATCH($B23,IncomeCalcs!$AF$2:$AK$2,0))} -> 0 | H23: {=INDEX(IncomeCalcs!$AF$2:$AK$254,MATCH(DATEVALUE(MATCH(H$2,{"January","February","March","April","May","June","July","August","September","October","November","December"},0) & "/1/" &$C$1),IncomeCalcs!$AE$2:$AE37,0),MATCH($B23,IncomeCalcs!$AF$2:$AK$2,0))} -> 0 | I23: =SUM(C23:H23) -> 0
A24: Donations | B24: Monthly totals: | C24: =sum(C$25:C$30) -> 0 | D24: =sum(D$25:D$30) -> 76.77 | E24: =sum(E$25:E$30) -> 41.13 | F24: =sum(F$25:F$30) -> 54.82 | G24: =sum(G$25:G$30) -> 0 | H24: =sum(H$25:H$30) -> 0 | I24: =SUM(C24:H24) -> 172.72
B25: Paypal | C25: {=INDEX(IncomeCalcs!$AN$2:$AS$254,MATCH(DATEVALUE(MATCH(C$2,{"January","February","March","April","May","June","July","August","September","October","November","December"},0) & "/1/" &$C$1),IncomeCalcs!$AM$2:$AM37,0),MATCH($B11,IncomeCalcs!$AN$2:$AS$2,0))} -> 0 | D25: {=INDEX(IncomeCalcs!$AN$2:$AS$254,MATCH(DATEVALUE(MATCH(D$2,{"January","February","March","April","May","June","July","August","September","October","November","December"},0) & "/1/" &$C$1),IncomeCalcs!$AM$2:$AM37,0),MATCH($B11,IncomeCalcs!$AN$2:$AS$2,0))} -> 61.77 | E25: {=INDEX(IncomeCalcs!$AN$2:$AS$254,MATCH(DATEVALUE(MATCH(E$2,{"January","February","March","April","May","June","July","August","September","October","November","December"},0) & "/1/" &$C$1),IncomeCalcs!$AM$2:$AM37,0),MATCH($B11,IncomeCalcs!$AN$2:$AS$2,0))} -> 38.13 | F25: {=INDEX(IncomeCalcs!$AN$2:$AS$254,MATCH(DATEVALUE(MATCH(F$2,{"January","February","March","April","May","June","July","August","September","October","November","December"},0) & "/1/" &$C$1),IncomeCalcs!$AM$2:$AM37,0),MATCH($B11,IncomeCalcs!$AN$2:$AS$2,0))} -> 5.82 | G25: {=INDEX(IncomeCalcs!$AN$2:$AS$254,MATCH(DATEVALUE(MATCH(G$2,{"January","February","March","April","May","June","July","August","September","October","November","December"},0) & "/1/" &$C$1),IncomeCalcs!$AM$2:$AM37,0),MATCH($B11,IncomeCalcs!$AN$2:$AS$2,0))} -> 0 | H25: {=INDEX(IncomeCalcs!$AN$2:$AS$254,MATCH(DATEVALUE(MATCH(H$2,{"January","February","March","April","May","June","July","August","September","October","November","December"},0) & "/1/" &$C$1),IncomeCalcs!$AM$2:$AM37,0),MATCH($B11,IncomeCalcs!$AN$2:$AS$2,0))} -> 0 | I25: =SUM(C25:H25) -> 105.72
B26: Cashapp | C26: {=INDEX(IncomeCalcs!$AN$2:$AS$254,MATCH(DATEVALUE(MATCH(C$2,{"January","February","March","April","May","June","July","August","September","October","November","December"},0) & "/1/" &$C$1),IncomeCalcs!$AM$2:$AM37,0),MATCH($B12,IncomeCalcs!$AN$2:$AS$2,0))} -> 0 | D26: {=INDEX(IncomeCalcs!$AN$2:$AS$254,MATCH(DATEVALUE(MATCH(D$2,{"January","February","March","April","May","June","July","August","September","October","November","December"},0) & "/1/" &$C$1),IncomeCalcs!$AM$2:$AM37,0),MATCH($B12,IncomeCalcs!$AN$2:$AS$2,0))} -> 10 | E26: {=INDEX(IncomeCalcs!$AN$2:$AS$254,MATCH(DATEVALUE(MATCH(E$2,{"January","February","March","April","May","June","July","August","September","October","November","December"},0) & "/1/" &$C$1),IncomeCalcs!$AM$2:$AM37,0),MATCH($B12,IncomeCalcs!$AN$2:$AS$2,0))} -> 3 | F26: {=INDEX(IncomeCalcs!$AN$2:$AS$254,MATCH(DATEVALUE(MATCH(F$2,{"January","February","March","April","May","June","July","August","September","October","November","December"},0) & "/1/" &$C$1),IncomeCalcs!$AM$2:$AM37,0),MATCH($B12,IncomeCalcs!$AN$2:$AS$2,0))} -> 0 | G26: {=INDEX(IncomeCalcs!$AN$2:$AS$254,MATCH(DATEVALUE(MATCH(G$2,{"January","February","March","April","May","June","July","August","September","October","November","December"},0) & "/1/" &$C$1),IncomeCalcs!$AM$2:$AM37,0),MATCH($B12,IncomeCalcs!$AN$2:$AS$2,0))} -> 0 | H26: {=INDEX(IncomeCalcs!$AN$2:$AS$254,MATCH(DATEVALUE(MATCH(H$2,{"January","February","March","April","May","June","July","August","September","October","November","December"},0) & "/1/" &$C$1),IncomeCalcs!$AM$2:$AM37,0),MATCH($B12,IncomeCalcs!$AN$2:$AS$2,0))} -> 0 | I26: =SUM(C26:H26) -> 13
B27: Venmo | C27: {=INDEX(IncomeCalcs!$AN$2:$AS$254,MATCH(DATEVALUE(MATCH(C$2,{"January","February","March","April","May","June","July","August","September","October","November","December"},0) & "/1/" &$C$1),IncomeCalcs!$AM$2:$AM37,0),MATCH($B13,IncomeCalcs!$AN$2:$AS$2,0))} -> 0 | D27: {=INDEX(IncomeCalcs!$AN$2:$AS$254,MATCH(DATEVALUE(MATCH(D$2,{"January","February","March","April","May","June","July","August","September","October","November","December"},0) & "/1/" &$C$1),IncomeCalcs!$AM$2:$AM37,0),MATCH($B13,IncomeCalcs!$AN$2:$AS$2,0))} -> 5 | E27: {=INDEX(IncomeCalcs!$AN$2:$AS$254,MATCH(DATEVALUE(MATCH(E$2,{"January","February","March","April","May","June","July","August","September","October","November","December"},0) & "/1/" &$C$1),IncomeCalcs!$AM$2:$AM37,0),MATCH($B13,IncomeCalcs!$AN$2:$AS$2,0))} -> 0 | F27: {=INDEX(IncomeCalcs!$AN$2:$AS$254,MATCH(DATEVALUE(MATCH(F$2,{"January","February","March","April","May","June","July","August","September","October","November","December"},0) & "/1/" &$C$1),IncomeCalcs!$AM$2:$AM37,0),MATCH($B13,IncomeCalcs!$AN$2:$AS$2,0))} -> 49 | G27: {=INDEX(IncomeCalcs!$AN$2:$AS$254,MATCH(DATEVALUE(MATCH(G$2,{"January","February","March","April","May","June","July","August","September","October","November","December"},0) & "/1/" &$C$1),IncomeCalcs!$AM$2:$AM37,0),MATCH($B13,IncomeCalcs!$AN$2:$AS$2,0))} -> 0 | H27: {=INDEX(IncomeCalcs!$AN$2:$AS$254,MATCH(DATEVALUE(MATCH(H$2,{"January","February","March","April","May","June","July","August","September","October","November","December"},0) & "/1/" &$C$1),IncomeCalcs!$AM$2:$AM37,0),MATCH($B13,IncomeCalcs!$AN$2:$AS$2,0))} -> 0 | I27: =SUM(C27:H27) -> 54
B28: Cash$ | C28: {=INDEX(IncomeCalcs!$AN$2:$AS$254,MATCH(DATEVALUE(MATCH(C$2,{"January","February","March","April","May","June","July","August","September","October","November","December"},0) & "/1/" &$C$1),IncomeCalcs!$AM$2:$AM37,0),MATCH($B14,IncomeCalcs!$AN$2:$AS$2,0))} -> 0 | D28: {=INDEX(IncomeCalcs!$AN$2:$AS$254,MATCH(DATEVALUE(MATCH(D$2,{"January","February","March","April","May","June","July","August","September","October","November","December"},0) & "/1/" &$C$1),IncomeCalcs!$AM$2:$AM37,0),MATCH($B14,IncomeCalcs!$AN$2:$AS$2,0))} -> 0 | E28: {=INDEX(IncomeCalcs!$AN$2:$AS$254,MATCH(DATEVALUE(MATCH(E$2,{"January","February","March","April","May","June","July","August","September","October","November","December"},0) & "/1/" &$C$1),IncomeCalcs!$AM$2:$AM37,0),MATCH($B14,IncomeCalcs!$AN$2:$AS$2,0))} -> 0 | F28: {=INDEX(IncomeCalcs!$AN$2:$AS$254,MATCH(DATEVALUE(MATCH(F$2,{"January","February","March","April","May","June","July","August","September","October","November","December"},0) & "/1/" &$C$1),IncomeCalcs!$AM$2:$AM37,0),MATCH($B14,IncomeCalcs!$AN$2:$AS$2,0))} -> 0 | G28: {=INDEX(IncomeCalcs!$AN$2:$AS$254,MATCH(DATEVALUE(MATCH(G$2,{"January","February","March","April","May","June","July","August","September","October","November","December"},0) & "/1/" &$C$1),IncomeCalcs!$AM$2:$AM37,0),MATCH($B14,IncomeCalcs!$AN$2:$AS$2,0))} -> 0 | H28: {=INDEX(IncomeCalcs!$AN$2:$AS$254,MATCH(DATEVALUE(MATCH(H$2,{"January","February","March","April","May","June","July","August","September","October","November","December"},0) & "/1/" &$C$1),IncomeCalcs!$AM$2:$AM37,0),MATCH($B14,IncomeCalcs!$AN$2:$AS$2,0))} -> 0 | I28: =SUM(C28:H28) -> 0
B29: Zelle | C29: {=INDEX(IncomeCalcs!$AN$2:$AS$254,MATCH(DATEVALUE(MATCH(C$2,{"January","February","March","April","May","June","July","August","September","October","November","December"},0) & "/1/" &$C$1),IncomeCalcs!$AM$2:$AM37,0),MATCH($B15,IncomeCalcs!$AN$2:$AS$2,0))} -> 0 | D29: {=INDEX(IncomeCalcs!$AN$2:$AS$254,MATCH(DATEVALUE(MATCH(D$2,{"January","February","March","April","May","June","July","August","September","October","November","December"},0) & "/1/" &$C$1),IncomeCalcs!$AM$2:$AM37,0),MATCH($B15,IncomeCalcs!$AN$2:$AS$2,0))} -> 0 | E29: {=INDEX(IncomeCalcs!$AN$2:$AS$254,MATCH(DATEVALUE(MATCH(E$2,{"January","February","March","April","May","June","July","August","September","October","November","December"},0) & "/1/" &$C$1),IncomeCalcs!$AM$2:$AM37,0),MATCH($B15,IncomeCalcs!$AN$2:$AS$2,0))} -> 0 | F29: {=INDEX(IncomeCalcs!$AN$2:$AS$254,MATCH(DATEVALUE(MATCH(F$2,{"January","February","March","April","May","June","July","August","September","October","November","December"},0) & "/1/" &$C$1),IncomeCalcs!$AM$2:$AM37,0),MATCH($B15,IncomeCalcs!$AN$2:$AS$2,0))} -> 0 | G29: {=INDEX(IncomeCalcs!$AN$2:$AS$254,MATCH(DATEVALUE(MATCH(G$2,{"January","February","March","April","May","June","July","August","September","October","November","December"},0) & "/1/" &$C$1),IncomeCalcs!$AM$2:$AM37,0),MATCH($B15,IncomeCalcs!$AN$2:$AS$2,0))} -> 0 | H29: {=INDEX(IncomeCalcs!$AN$2:$AS$254,MATCH(DATEVALUE(MATCH(H$2,{"January","February","March","April","May","June","July","August","September","October","November","December"},0) & "/1/" &$C$1),IncomeCalcs!$AM$2:$AM37,0),MATCH($B15,IncomeCalcs!$AN$2:$AS$2,0))} -> 0 | I29: =SUM(C29:H29) -> 0
B30: GoFundMe | C30: {=INDEX(IncomeCalcs!$AN$2:$AS$254,MATCH(DATEVALUE(MATCH(C$2,{"January","February","March","April","May","June","July","August","September","October","November","December"},0) & "/1/" &$C$1),IncomeCalcs!$AM$2:$AM37,0),MATCH($B16,IncomeCalcs!$AN$2:$AS$2,0))} -> 0 | D30: {=INDEX(IncomeCalcs!$AN$2:$AS$254,MATCH(DATEVALUE(MATCH(D$2,{"January","February","March","April","May","June","July","August","September","October","November","December"},0) & "/1/" &$C$1),IncomeCalcs!$AM$2:$AM37,0),MATCH($B16,IncomeCalcs!$AN$2:$AS$2,0))} -> 0 | E30: {=INDEX(IncomeCalcs!$AN$2:$AS$254,MATCH(DATEVALUE(MATCH(E$2,{"January","February","March","April","May","June","July","August","September","October","November","December"},0) & "/1/" &$C$1),IncomeCalcs!$AM$2:$AM37,0),MATCH($B16,IncomeCalcs!$AN$2:$AS$2,0))} -> 0 | F30: {=INDEX(IncomeCalcs!$AN$2:$AS$254,MATCH(DATEVALUE(MATCH(F$2,{"January","February","March","April","May","June","July","August","September","October","November","December"},0) & "/1/" &$C$1),IncomeCalcs!$AM$2:$AM37,0),MATCH($B16,IncomeCalcs!$AN$2:$AS$2,0))} -> 0 | G30: {=INDEX(IncomeCalcs!$AN$2:$AS$254,MATCH(DATEVALUE(MATCH(G$2,{"January","February","March","April","May","June","July","August","September","October","November","December"},0) & "/1/" &$C$1),IncomeCalcs!$AM$2:$AM37,0),MATCH($B16,IncomeCalcs!$AN$2:$AS$2,0))} -> 0 | H30: {=INDEX(IncomeCalcs!$AN$2:$AS$254,MATCH(DATEVALUE(MATCH(H$2,{"January","February","March","April","May","June","July","August","September","October","November","December"},0) & "/1/" &$C$1),IncomeCalcs!$AM$2:$AM37,0),MATCH($B16,IncomeCalcs!$AN$2:$AS$2,0))} -> 0 | I30: =SUM(C30:H30) -> 0
A31: Adoption fees | B31: Monthly totals: | C31: =sum(C$32:C$37) -> 0 | D31: =sum(D$32:D$37) -> 0 | E31: =sum(E$32:E$37) -> 0 | F31: =sum(F$32:F$37) -> 0 | G31: =sum(G$32:G$37) -> 0 | H31: =sum(H$32:H$37) -> 0 | I31: =SUM(C31:H31) -> 0
B32: Paypal | C32: {=INDEX(IncomeCalcs!$AV$2:$BA$254,MATCH(DATEVALUE(MATCH(C$2,{"January","February","March","April","May","June","July","August","September","October","November","December"},0) & "/1/" &$C$1),IncomeCalcs!$AU$2:$AU37,0),MATCH($B11,IncomeCalcs!$AV$2:$BA$2,0))} -> 0 | D32: {=INDEX(IncomeCalcs!$AV$2:$BA$254,MATCH(DATEVALUE(MATCH(D$2,{"January","February","March","April","May","June","July","August","September","October","November","December"},0) & "/1/" &$C$1),IncomeCalcs!$AU$2:$AU37,0),MATCH($B11,IncomeCalcs!$AV$2:$BA$2,0))} -> 0 | E32: {=INDEX(IncomeCalcs!$AV$2:$BA$254,MATCH(DATEVALUE(MATCH(E$2,{"January","February","March","April","May","June","July","August","September","October","November","December"},0) & "/1/" &$C$1),IncomeCalcs!$AU$2:$AU37,0),MATCH($B11,IncomeCalcs!$AV$2:$BA$2,0))} -> 0 | F32: {=INDEX(IncomeCalcs!$AV$2:$BA$254,MATCH(DATEVALUE(MATCH(F$2,{"January","February","March","April","May","June","July","August","September","October","November","December"},0) & "/1/" &$C$1),IncomeCalcs!$AU$2:$AU37,0),MATCH($B11,IncomeCalcs!$AV$2:$BA$2,0))} -> 0 | G32: {=INDEX(IncomeCalcs!$AV$2:$BA$254,MATCH(DATEVALUE(MATCH(G$2,{"January","February","March","April","May","June","July","August","September","October","November","December"},0) & "/1/" &$C$1),IncomeCalcs!$AU$2:$AU37,0),MATCH($B11,IncomeCalcs!$AV$2:$BA$2,0))} -> 0 | H32: {=INDEX(IncomeCalcs!$AV$2:$BA$254,MATCH(DATEVALUE(MATCH(H$2,{"January","February","March","April","May","June","July","August","September","October","November","December"},0) & "/1/" &$C$1),IncomeCalcs!$AU$2:$AU37,0),MATCH($B11,IncomeCalcs!$AV$2:$BA$2,0))} -> 0 | I32: =SUM(C32:H32) -> 0
B33: Cashapp | C33: {=INDEX(IncomeCalcs!$AV$2:$BA$254,MATCH(DATEVALUE(MATCH(C$2,{"January","February","March","April","May","June","July","August","September","October","November","December"},0) & "/1/" &$C$1),IncomeCalcs!$AU$2:$AU37,0),MATCH($B12,IncomeCalcs!$AV$2:$BA$2,0))} -> 0 | D33: {=INDEX(IncomeCalcs!$AV$2:$BA$254,MATCH(DATEVALUE(MATCH(D$2,{"January","February","March","April","May","June","July","August","September","October","November","December"},0) & "/1/" &$C$1),IncomeCalcs!$AU$2:$AU37,0),MATCH($B12,IncomeCalcs!$AV$2:$BA$2,0))} -> 0 | E33: {=INDEX(IncomeCalcs!$AV$2:$BA$254,MATCH(DATEVALUE(MATCH(E$2,{"January","February","March","April","May","June","July","August","September","October","November","December"},0) & "/1/" &$C$1),IncomeCalcs!$AU$2:$AU37,0),MATCH($B12,IncomeCalcs!$AV$2:$BA$2,0))} -> 0 | F33: {=INDEX(IncomeCalcs!$AV$2:$BA$254,MATCH(DATEVALUE(MATCH(F$2,{"January","February","March","April","May","June","July","August","September","October","November","December"},0) & "/1/" &$C$1),IncomeCalcs!$AU$2:$AU37,0),MATCH($B12,IncomeCalcs!$AV$2:$BA$2,0))} -> 0 | G33: {=INDEX(IncomeCalcs!$AV$2:$BA$254,MATCH(DATEVALUE(MATCH(G$2,{"January","February","March","April","May","June","July","August","September","October","November","December"},0) & "/1/" &$C$1),IncomeCalcs!$AU$2:$AU37,0),MATCH($B12,IncomeCalcs!$AV$2:$BA$2,0))} -> 0 | H33: {=INDEX(IncomeCalcs!$AV$2:$BA$254,MATCH(DATEVALUE(MATCH(H$2,{"January","February","March","April","May","June","July","August","September","October","November","December"},0) & "/1/" &$C$1),IncomeCalcs!$AU$2:$AU37,0),MATCH($B12,IncomeCalcs!$AV$2:$BA$2,0))} -> 0 | I33: =SUM(C33:H33) -> 0
B34: Venmo | C34: {=INDEX(IncomeCalcs!$AV$2:$BA$254,MATCH(DATEVALUE(MATCH(C$2,{"January","February","March","April","May","June","July","August","September","October","November","December"},0) & "/1/" &$C$1),IncomeCalcs!$AU$2:$AU37,0),MATCH($B13,IncomeCalcs!$AV$2:$BA$2,0))} -> 0 | D34: {=INDEX(IncomeCalcs!$AV$2:$BA$254,MATCH(DATEVALUE(MATCH(D$2,{"January","February","March","April","May","June","July","August","September","October","November","December"},0) & "/1/" &$C$1),IncomeCalcs!$AU$2:$AU37,0),MATCH($B13,IncomeCalcs!$AV$2:$BA$2,0))} -> 0 | E34: {=INDEX(IncomeCalcs!$AV$2:$BA$254,MATCH(DATEVALUE(MATCH(E$2,{"January","February","March","April","May","June","July","August","September","October","November","December"},0) & "/1/" &$C$1),IncomeCalcs!$AU$2:$AU37,0),MATCH($B13,IncomeCalcs!$AV$2:$BA$2,0))} -> 0 | F34: {=INDEX(IncomeCalcs!$AV$2:$BA$254,MATCH(DATEVALUE(MATCH(F$2,{"January","February","March","April","May","June","July","August","September","October","November","December"},0) & "/1/" &$C$1),IncomeCalcs!$AU$2:$AU37,0),MATCH($B13,IncomeCalcs!$AV$2:$BA$2,0))} -> 0 | G34: {=INDEX(IncomeCalcs!$AV$2:$BA$254,MATCH(DATEVALUE(MATCH(G$2,{"January","February","March","April","May","June","July","August","September","October","November","December"},0) & "/1/" &$C$1),IncomeCalcs!$AU$2:$AU37,0),MATCH($B13,IncomeCalcs!$AV$2:$BA$2,0))} -> 0 | H34: {=INDEX(IncomeCalcs!$AV$2:$BA$254,MATCH(DATEVALUE(MATCH(H$2,{"January","February","March","April","May","June","July","August","September","October","November","December"},0) & "/1/" &$C$1),IncomeCalcs!$AU$2:$AU37,0),MATCH($B13,IncomeCalcs!$AV$2:$BA$2,0))} -> 0 | I34: =SUM(C34:H34) -> 0
B35: Cash$ | C35: {=INDEX(IncomeCalcs!$AV$2:$BA$254,MATCH(DATEVALUE(MATCH(C$2,{"January","February","March","April","May","June","July","August","September","October","November","December"},0) & "/1/" &$C$1),IncomeCalcs!$AU$2:$AU37,0),MATCH($B14,IncomeCalcs!$AV$2:$BA$2,0))} -> 0 | D35: {=INDEX(IncomeCalcs!$AV$2:$BA$254,MATCH(DATEVALUE(MATCH(D$2,{"January","February","March","April","May","June","July","August","September","October","November","December"},0) & "/1/" &$C$1),IncomeCalcs!$AU$2:$AU37,0),MATCH($B14,IncomeCalcs!$AV$2:$BA$2,0))} -> 0 | E35: {=INDEX(IncomeCalcs!$AV$2:$BA$254,MATCH(DATEVALUE(MATCH(E$2,{"January","February","March","April","May","June","July","August","September","October","November","December"},0) & "/1/" &$C$1),IncomeCalcs!$AU$2:$AU37,0),MATCH($B14,IncomeCalcs!$AV$2:$BA$2,0))} -> 0 | F35: {=INDEX(IncomeCalcs!$AV$2:$BA$254,MATCH(DATEVALUE(MATCH(F$2,{"January","February","March","April","May","June","July","August","September","October","November","December"},0) & "/1/" &$C$1),IncomeCalcs!$AU$2:$AU37,0),MATCH($B14,IncomeCalcs!$AV$2:$BA$2,0))} -> 0 | G35: {=INDEX(IncomeCalcs!$AV$2:$BA$254,MATCH(DATEVALUE(MATCH(G$2,{"January","February","March","April","May","June","July","August","September","October","November","December"},0) & "/1/" &$C$1),IncomeCalcs!$AU$2:$AU37,0),MATCH($B14,IncomeCalcs!$AV$2:$BA$2,0))} -> 0 | H35: {=INDEX(IncomeCalcs!$AV$2:$BA$254,MATCH(DATEVALUE(MATCH(H$2,{"January","February","March","April","May","June","July","August","September","October","November","December"},0) & "/1/" &$C$1),IncomeCalcs!$AU$2:$AU37,0),MATCH($B14,IncomeCalcs!$AV$2:$BA$2,0))} -> 0 | I35: =SUM(C35:H35) -> 0
B36: Zelle | C36: {=INDEX(IncomeCalcs!$AV$2:$BA$254,MATCH(DATEVALUE(MATCH(C$2,{"January","February","March","April","May","June","July","August","September","October","November","December"},0) & "/1/" &$C$1),IncomeCalcs!$AU$2:$AU37,0),MATCH($B15,IncomeCalcs!$AV$2:$BA$2,0))} -> 0 | D36: {=INDEX(IncomeCalcs!$AV$2:$BA$254,MATCH(DATEVALUE(MATCH(D$2,{"January","February","March","April","May","June","July","August","September","October","November","December"},0) & "/1/" &$C$1),IncomeCalcs!$AU$2:$AU37,0),MATCH($B15,IncomeCalcs!$AV$2:$BA$2,0))} -> 0 | E36: {=INDEX(IncomeCalcs!$AV$2:$BA$254,MATCH(DATEVALUE(MATCH(E$2,{"January","February","March","April","May","June","July","August","September","October","November","December"},0) & "/1/" &$C$1),IncomeCalcs!$AU$2:$AU37,0),MATCH($B15,IncomeCalcs!$AV$2:$BA$2,0))} -> 0 | F36: {=INDEX(IncomeCalcs!$AV$2:$BA$254,MATCH(DATEVALUE(MATCH(F$2,{"January","February","March","April","May","June","July","August","September","October","November","December"},0) & "/1/" &$C$1),IncomeCalcs!$AU$2:$AU37,0),MATCH($B15,IncomeCalcs!$AV$2:$BA$2,0))} -> 0 | G36: {=INDEX(IncomeCalcs!$AV$2:$BA$254,MATCH(DATEVALUE(MATCH(G$2,{"January","February","March","April","May","June","July","August","September","October","November","December"},0) & "/1/" &$C$1),IncomeCalcs!$AU$2:$AU37,0),MATCH($B15,IncomeCalcs!$AV$2:$BA$2,0))} -> 0 | H36: {=INDEX(IncomeCalcs!$AV$2:$BA$254,MATCH(DATEVALUE(MATCH(H$2,{"January","February","March","April","May","June","July","August","September","October","November","December"},0) & "/1/" &$C$1),IncomeCalcs!$AU$2:$AU37,0),MATCH($B15,IncomeCalcs!$AV$2:$BA$2,0))} -> 0 | I36: =SUM(C36:H36) -> 0
B37: GoFundMe | C37: {=INDEX(IncomeCalcs!$AV$2:$BA$254,MATCH(DATEVALUE(MATCH(C$2,{"January","February","March","April","May","June","July","August","September","October","November","December"},0) & "/1/" &$C$1),IncomeCalcs!$AU$2:$AU37,0),MATCH($B16,IncomeCalcs!$AV$2:$BA$2,0))} -> 0 | D37: {=INDEX(IncomeCalcs!$AV$2:$BA$254,MATCH(DATEVALUE(MATCH(D$2,{"January","February","March","April","May","June","July","August","September","October","November","December"},0) & "/1/" &$C$1),IncomeCalcs!$AU$2:$AU37,0),MATCH($B16,IncomeCalcs!$AV$2:$BA$2,0))} -> 0 | E37: {=INDEX(IncomeCalcs!$AV$2:$BA$254,MATCH(DATEVALUE(MATCH(E$2,{"January","February","March","April","May","June","July","August","September","October","November","December"},0) & "/1/" &$C$1),IncomeCalcs!$AU$2:$AU37,0),MATCH($B16,IncomeCalcs!$AV$2:$BA$2,0))} -> 0 | F37: {=INDEX(IncomeCalcs!$AV$2:$BA$254,MATCH(DATEVALUE(MATCH(F$2,{"January","February","March","April","May","June","July","August","September","October","November","December"},0) & "/1/" &$C$1),IncomeCalcs!$AU$2:$AU37,0),MATCH($B16,IncomeCalcs!$AV$2:$BA$2,0))} -> 0 | G37: {=INDEX(IncomeCalcs!$AV$2:$BA$254,MATCH(DATEVALUE(MATCH(G$2,{"January","February","March","April","May","June","July","August","September","October","November","December"},0) & "/1/" &$C$1),IncomeCalcs!$AU$2:$AU37,0),MATCH($B16,IncomeCalcs!$AV$2:$BA$2,0))} -> 0 | H37: {=INDEX(IncomeCalcs!$AV$2:$BA$254,MATCH(DATEVALUE(MATCH(H$2,{"January","February","March","April","May","June","July","August","September","October","November","December"},0) & "/1/" &$C$1),IncomeCalcs!$AU$2:$AU37,0),MATCH($B16,IncomeCalcs!$AV$2:$BA$2,0))} -> 0 | I37: =SUM(C37:H37) -> 0

Sheet Membership Application List
A1: Membership Application List
A2: Original form linked here: https://docs.google.com/spreadsheets/d/18RaQw448NnENcNftounuam8eQyPVXS6StgZUz-RLzHA/edit?usp=sharing
A3: Date | B3: Mavorgs Invite | C3: Semester | D3: Email | E3: Full Name | F3: Discord Username | G3: Payment Username | H3: Phone Number | I3: Membership Type | J3: Dues Or Donation | K3: Discount (Social Media) | L3: Paid Where? | M3: Donation? | N3: Verified? | O3: Committee Interests | P3: Images (Proof of payment) | Q3: Officer Notes
